Workbook

Sheet Summary- FY 25-26
A1: CEO Of the Quarter | J1: Job Well Done
A3: Region / Quarters | B3: Q1-FY26 | C3: Q2-FY26 | D3: Q3-FY26 | E3: Q4-FY26 | F3: Total | J3: Region / Quarters | K3: Q1-FY26 | L3: Q2-FY26 | M3: Q3-FY26 | N3: Q4-FY26 | O3: Total
A4: Corporate | B4: =COUNTIFS('CEO of the Qtr'!$H:$H,'Summary- FY 25-26'!$A$4,'CEO of the Qtr'!$I:$I,'Summary- FY 25-26'!B3) -> 9 | C4: =COUNTIFS('CEO of the Qtr'!$H:$H,'Summary- FY 25-26'!$A$4,'CEO of the Qtr'!$I:$I,'Summary- FY 25-26'!C3) -> 0 | D4: =COUNTIFS('CEO of the Qtr'!$H:$H,'Summary- FY 25-26'!$A$4,'CEO of the Qtr'!$I:$I,'Summary- FY 25-26'!D3) -> 0 | E4: =COUNTIFS('CEO of the Qtr'!$H:$H,'Summary- FY 25-26'!$A$4,'CEO of the Qtr'!$I:$I,'Summary- FY 25-26'!E3) -> 0 | F4: =SUM(B4:E4) -> 9 | J4: Corporate | K4: =COUNTIFS('Job Well Done'!$F:$F,K3,'Job Well Done'!$J:$J,$J$4) -> 6 | L4: =COUNTIFS('Job Well Done'!$F:$F,L3,'Job Well Done'!$J:$J,$J$4) -> 0 | M4: =COUNTIFS('Job Well Done'!$F:$F,M3,'Job Well Done'!$J:$J,$J$4) -> 0 | N4: =COUNTIFS('Job Well Done'!$F:$F,N3,'Job Well Done'!$J:$J,$J$4) -> 0 | O4: =SUM(K4:N4) -> 6
A5: West | B5: =COUNTIFS('CEO of the Qtr'!$H:$H,'Summary- FY 25-26'!$A$5,'CEO of the Qtr'!$I:$I,'Summary- FY 25-26'!B3) -> 0 | C5: =COUNTIFS('CEO of the Qtr'!$H:$H,'Summary- FY 25-26'!$A$5,'CEO of the Qtr'!$I:$I,'Summary- FY 25-26'!C3) -> 0 | D5: =COUNTIFS('CEO of the Qtr'!$H:$H,'Summary- FY 25-26'!$A$5,'CEO of the Qtr'!$I:$I,'Summary- FY 25-26'!D3) -> 0 | E5: =COUNTIFS('CEO of the Qtr'!$H:$H,'Summary- FY 25-26'!$A$5,'CEO of the Qtr'!$I:$I,'Summary- FY 25-26'!E3) -> 0 | F5: =SUM(B5:E5) -> 0 | J5: West | K5: =COUNTIFS('Job Well Done'!$F:$F,K3,'Job Well Done'!$J:$J,$J$5) -> 5 | L5: =COUNTIFS('Job Well Done'!$F:$F,L3,'Job Well Done'!$J:$J,$J$5) -> 0 | M5: =COUNTIFS('Job Well Done'!$F:$F,M3,'Job Well Done'!$J:$J,$J$5) -> 0 | N5: =COUNTIFS('Job Well Done'!$F:$F,N3,'Job Well Done'!$J:$J,$J$5) -> 0 | O5: =SUM(K5:N5) -> 5
A6: East | B6: =COUNTIFS('CEO of the Qtr'!$H:$H,'Summary- FY 25-26'!$A$6,'CEO of the Qtr'!$I:$I,'Summary- FY 25-26'!B3) -> 0 | C6: =COUNTIFS('CEO of the Qtr'!$H:$H,'Summary- FY 25-26'!$A$6,'CEO of the Qtr'!$I:$I,'Summary- FY 25-26'!C3) -> 0 | D6: =COUNTIFS('CEO of the Qtr'!$H:$H,'Summary- FY 25-26'!$A$6,'CEO of the Qtr'!$I:$I,'Summary- FY 25-26'!D3) -> 0 | E6: =COUNTIFS('CEO of the Qtr'!$H:$H,'Summary- FY 25-26'!$A$6,'CEO of the Qtr'!$I:$I,'Summary- FY 25-26'!E3) -> 0 | F6: =SUM(B6:E6) -> 0 | J6: East | K6: =COUNTIFS('Job Well Done'!$F:$F,K3,'Job Well Done'!$J:$J,$J$6) -> 2 | L6: =COUNTIFS('Job Well Done'!$F:$F,L3,'Job Well Done'!$J:$J,$J$6) -> 0 | M6: =COUNTIFS('Job Well Done'!$F:$F,M3,'Job Well Done'!$J:$J,$J$6) -> 0 | N6: =COUNTIFS('Job Well Done'!$F:$F,N3,'Job Well Done'!$J:$J,$J$6) -> 0 | O6: =SUM(K6:N6) -> 2
A7: North | B7: =COUNTIFS('CEO of the Qtr'!$H:$H,'Summary- FY 25-26'!$A$7,'CEO of the Qtr'!$I:$I,'Summary- FY 25-26'!B3) -> 4 | C7: =COUNTIFS('CEO of the Qtr'!$H:$H,'Summary- FY 25-26'!$A$7,'CEO of the Qtr'!$I:$I,'Summary- FY 25-26'!C3) -> 0 | D7: =COUNTIFS('CEO of the Qtr'!$H:$H,'Summary- FY 25-26'!$A$7,'CEO of the Qtr'!$I:$I,'Summary- FY 25-26'!D3) -> 0 | E7: =COUNTIFS('CEO of the Qtr'!$H:$H,'Summary- FY 25-26'!$A$7,'CEO of the Qtr'!$I:$I,'Summary- FY 25-26'!E3) -> 0 | F7: =SUM(B7:E7) -> 4 | J7: North | K7: =COUNTIFS('Job Well Done'!$F:$F,K3,'Job Well Done'!$J:$J,$J$7) -> 3 | L7: =COUNTIFS('Job Well Done'!$F:$F,L3,'Job Well Done'!$J:$J,$J$7) -> 0 | M7: =COUNTIFS('Job Well Done'!$F:$F,M3,'Job Well Done'!$J:$J,$J$7) -> 0 | N7: =COUNTIFS('Job Well Done'!$F:$F,N3,'Job Well Done'!$J:$J,$J$7) -> 0 | O7: =SUM(K7:N7) -> 3
A8: South | B8: =COUNTIFS('CEO of the Qtr'!$H:$H,'Summary- FY 25-26'!$A$8,'CEO of the Qtr'!$I:$I,'Summary- FY 25-26'!B3) -> 14 | C8: =COUNTIFS('CEO of the Qtr'!$H:$H,'Summary- FY 25-26'!$A$8,'CEO of the Qtr'!$I:$I,'Summary- FY 25-26'!C3) -> 0 | D8: =COUNTIFS('CEO of the Qtr'!$H:$H,'Summary- FY 25-26'!$A$8,'CEO of the Qtr'!$I:$I,'Summary- FY 25-26'!D3) -> 0 | E8: =COUNTIFS('CEO of the Qtr'!$H:$H,'Summary- FY 25-26'!$A$8,'CEO of the Qtr'!$I:$I,'Summary- FY 25-26'!E3) -> 0 | F8: =SUM(B8:E8) -> 14 | J8: South | K8: =COUNTIFS('Job Well Done'!$F:$F,K3,'Job Well Done'!$J:$J,$J$8) -> 5 | L8: =COUNTIFS('Job Well Done'!$F:$F,L3,'Job Well Done'!$J:$J,$J$8) -> 0 | M8: =COUNTIFS('Job Well Done'!$F:$F,M3,'Job Well Done'!$J:$J,$J$8) -> 0 | N8: =COUNTIFS('Job Well Done'!$F:$F,N3,'Job Well Done'!$J:$J,$J$8) -> 0 | O8: =SUM(K8:N8) -> 5
A9: Total | B9: =SUM(B4:B8) -> 27 | C9: =SUM(C4:C8) -> 0 | D9: =SUM(D4:D8) -> 0 | E9: =SUM(E4:E8) -> 0 | F9: =SUM(B9:E9) -> 27 | J9: Total | K9: =SUM(K4:K8) -> 21 | L9: =SUM(L4:L8) -> 0 | M9: =SUM(M4:M8) -> 0 | N9: =SUM(N4:N8) -> 0 | O9: =SUM(K9:N9) -> 21
A11: SPOT and SPOT of the Month | J11: Intrafunctional
B13: FY25-26 | C13: FY25-26 | J13: Q1-FY26 | K13: Q2-FY26 | L13: Q3-FY26 | M13: Q4-FY26 | N13: Total
A14: Region / Quarters | B14: SPOT | C14: Spot of the Month | J14: 2 | K14: 0 | L14: 0 | M14: 0 | N14: =SUM(J14:M14) -> 2
A15: Corporate | B15: =COUNTIFS('Spot & Spot of the Month'!$I:$I,A15,'Spot & Spot of the Month'!$F:$F,$B$14,'Spot & Spot of the Month'!L:L,'Summary- FY 25-26'!$B$13) -> 26 | C15: =COUNTIFS('Spot & Spot of the Month'!$I:$I,A15,'Spot & Spot of the Month'!$F:$F,$C$14,'Spot & Spot of the Month'!L:L,'Summary- FY 25-26'!$C$13) -> 28
A16: West | B16: =COUNTIFS('Spot & Spot of the Month'!$I:$I,A16,'Spot & Spot of the Month'!$F:$F,$B$14,'Spot & Spot of the Month'!L:L,'Summary- FY 25-26'!$B$13) -> 3 | C16: =COUNTIFS('Spot & Spot of the Month'!$I:$I,A16,'Spot & Spot of the Month'!$F:$F,$C$14,'Spot & Spot of the Month'!L:L,'Summary- FY 25-26'!$C$13) -> 2
A17: East | B17: =COUNTIFS('Spot & Spot of the Month'!$I:$I,A17,'Spot & Spot of the Month'!$F:$F,$B$14,'Spot & Spot of the Month'!L:L,'Summary- FY 25-26'!$B$13) -> 5 | C17: =COUNTIFS('Spot & Spot of the Month'!$I:$I,A17,'Spot & Spot of the Month'!$F:$F,$C$14,'Spot & Spot of the Month'!L:L,'Summary- FY 25-26'!$C$13) -> 9
A18: North | B18: =COUNTIFS('Spot & Spot of the Month'!$I:$I,A18,'Spot & Spot of the Month'!$F:$F,$B$14,'Spot & Spot of the Month'!L:L,'Summary- FY 25-26'!$B$13) -> 11 | C18: =COUNTIFS('Spot & Spot of the Month'!$I:$I,A18,'Spot & Spot of the Month'!$F:$F,$C$14,'Spot & Spot of the Month'!L:L,'Summary- FY 25-26'!$C$13) -> 13
A19: South | B19: =COUNTIFS('Spot & Spot of the Month'!$I:$I,A19,'Spot & Spot of the Month'!$F:$F,$B$14,'Spot & Spot of the Month'!L:L,'Summary- FY 25-26'!$B$13) -> 41 | C19: =COUNTIFS('Spot & Spot of the Month'!$I:$I,A19,'Spot & Spot of the Month'!$F:$F,$C$14,'Spot & Spot of the Month'!L:L,'Summary- FY 25-26'!$C$13) -> 42
A21: Debutant of the Quarter | J21: Cross Functional
A22: Region / Quarters | B22: Q1-FY26 | C22: Q2-FY26 | D22: Q3-FY26 | E22: Q4-FY26 | F22: Total
A23: Corporate | B23: =COUNTIFS('Debutant of the Qtr'!$F:$F,B22,'Debutant of the Qtr'!$J:$J,'Summary- FY 25-26'!$A$23) -> 3 | C23: =COUNTIFS('Debutant of the Qtr'!$F:$F,C22,'Debutant of the Qtr'!$J:$J,'Summary- FY 25-26'!$A$23) -> 0 | D23: =COUNTIFS('Debutant of the Qtr'!$F:$F,D22,'Debutant of the Qtr'!$J:$J,'Summary- FY 25-26'!$A$23) -> 0 | E23: =COUNTIFS('Debutant of the Qtr'!$F:$F,E22,'Debutant of the Qtr'!$J:$J,'Summary- FY 25-26'!$A$23) -> 0 | F23: =COUNTIFS('Debutant of the Qtr'!$F:$F,F22,'Debutant of the Qtr'!$J:$J,'Summary- FY 25-26'!$A$23) -> 0 | J23: Q1-FY26 | K23: Q2-FY26 | L23: Q3-FY26 | M23: Q4-FY26 | N23: Total
A24: West | B24: =COUNTIFS('Debutant of the Qtr'!$F:$F,B22,'Debutant of the Qtr'!$J:$J,'Summary- FY 25-26'!$A$24) -> 0 | C24: =COUNTIFS('Debutant of the Qtr'!$F:$F,C22,'Debutant of the Qtr'!$J:$J,'Summary- FY 25-26'!$A$24) -> 0 | D24: =COUNTIFS('Debutant of the Qtr'!$F:$F,D22,'Debutant of the Qtr'!$J:$J,'Summary- FY 25-26'!$A$24) -> 0 | E24: =COUNTIFS('Debutant of the Qtr'!$F:$F,E22,'Debutant of the Qtr'!$J:$J,'Summary- FY 25-26'!$A$24) -> 0 | F24: =COUNTIFS('Debutant of the Qtr'!$F:$F,F22,'Debutant of the Qtr'!$J:$J,'Summary- FY 25-26'!$A$24) -> 0 | J24: 1 | K24: =COUNTIF(Sheet4!$G:$G,K23) -> 0 | L24: =COUNTIF(Sheet4!$G:$G,L23) -> 0 | M24: =COUNTIF(Sheet4!$G:$G,M23) -> 0 | N24: =SUM(J24:M24) -> 1
A25: East | B25: =COUNTIFS('Debutant of the Qtr'!$F:$F,B22,'Debutant of the Qtr'!$J:$J,'Summary- FY 25-26'!$A$25) -> 0 | C25: =COUNTIFS('Debutant of the Qtr'!$F:$F,C22,'Debutant of the Qtr'!$J:$J,'Summary- FY 25-26'!$A$25) -> 0 | D25: =COUNTIFS('Debutant of the Qtr'!$F:$F,D22,'Debutant of the Qtr'!$J:$J,'Summary- FY 25-26'!$A$25) -> 0 | E25: =COUNTIFS('Debutant of the Qtr'!$F:$F,E22,'Debutant of the Qtr'!$J:$J,'Summary- FY 25-26'!$A$25) -> 0 | F25: =COUNTIFS('Debutant of the Qtr'!$F:$F,F22,'Debutant of the Qtr'!$J:$J,'Summary- FY 25-26'!$A$25) -> 0
A26: North | B26: =COUNTIFS('Debutant of the Qtr'!$F:$F,B22,'Debutant of the Qtr'!$J:$J,'Summary- FY 25-26'!$A$26) -> 0 | C26: =COUNTIFS('Debutant of the Qtr'!$F:$F,C22,'Debutant of the Qtr'!$J:$J,'Summary- FY 25-26'!$A$26) -> 0 | D26: =COUNTIFS('Debutant of the Qtr'!$F:$F,D22,'Debutant of the Qtr'!$J:$J,'Summary- FY 25-26'!$A$26) -> 0 | E26: =COUNTIFS('Debutant of the Qtr'!$F:$F,E22,'Debutant of the Qtr'!$J:$J,'Summary- FY 25-26'!$A$26) -> 0 | F26: =COUNTIFS('Debutant of the Qtr'!$F:$F,F22,'Debutant of the Qtr'!$J:$J,'Summary- FY 25-26'!$A$26) -> 0
A27: South | B27: =COUNTIFS('Debutant of the Qtr'!$F:$F,B22,'Debutant of the Qtr'!$J:$J,'Summary- FY 25-26'!$A$27) -> 0 | C27: =COUNTIFS('Debutant of the Qtr'!$F:$F,C22,'Debutant of the Qtr'!$J:$J,'Summary- FY 25-26'!$A$27) -> 0 | D27: =COUNTIFS('Debutant of the Qtr'!$F:$F,D22,'Debutant of the Qtr'!$J:$J,'Summary- FY 25-26'!$A$27) -> 0 | E27: =COUNTIFS('Debutant of the Qtr'!$F:$F,E22,'Debutant of the Qtr'!$J:$J,'Summary- FY 25-26'!$A$27) -> 0 | F27: =COUNTIFS('Debutant of the Qtr'!$F:$F,F22,'Debutant of the Qtr'!$J:$J,'Summary- FY 25-26'!$A$27) -> 0
B30: People Champion | J30: Thank You
A31: Region / Quarters | C31: Total | J31: Region / Quarters | K31: Total
A32: Corporate | C32: =SUM(B32) -> 0 | J32: Corporate | K32: =COUNTIFS('Thank You'!$I:$I,'Summary- FY 25-26'!J32) -> 19
A33: South | C33: =SUM(B33) -> 0 | J33: West | K33: =COUNTIFS('Thank You'!$I:$I,'Summary- FY 25-26'!J33) -> 9
J34: East | K34: =COUNTIFS('Thank You'!$I:$I,'Summary- FY 25-26'!J34) -> 9
J35: North | K35: =COUNTIFS('Thank You'!$I:$I,'Summary- FY 25-26'!J35) -> 22
J36: South | K36: =COUNTIFS('Thank You'!$I:$I,'Summary- FY 25-26'!J36) -> 47

Sheet Summary- FY 24-25
A1: CEO Of the Quarter | J1: Job Well Done
A3: Region / Quarters | B3: Q3-FY24 | C3: Q4-FY24 | D3: Q1-FY25 | E3: Q2-FY 25 | F3: Q3-FY25 | G3: Q4-FY25 | H3: Total | J3: Region / Quarters | K3: Q3-FY24 | L3: Q4-FY24 | M3: Q1-FY25 | N3: Q2-FY25 | O3: Q3-FY25 | P3: Q4-FY25 | Q3: Total
A4: Corporate | B4: =COUNTIFS('CEO of the Qtr'!$H:$H,'Summary- FY 24-25'!$A$4,'CEO of the Qtr'!$I:$I,'Summary- FY 24-25'!B3) -> 8 | C4: =COUNTIFS('CEO of the Qtr'!$H:$H,'Summary- FY 24-25'!$A$4,'CEO of the Qtr'!$I:$I,'Summary- FY 24-25'!C3) -> 8 | D4: =COUNTIFS('CEO of the Qtr'!$H:$H,'Summary- FY 24-25'!$A$4,'CEO of the Qtr'!$I:$I,'Summary- FY 24-25'!D3) -> 7 | E4: =COUNTIFS('CEO of the Qtr'!$H:$H,'Summary- FY 24-25'!$A$4,'CEO of the Qtr'!$I:$I,'Summary- FY 24-25'!E3) -> 9 | F4: =COUNTIFS('CEO of the Qtr'!$H:$H,'Summary- FY 24-25'!$A$4,'CEO of the Qtr'!$I:$I,'Summary- FY 24-25'!F3) -> 7 | G4: =COUNTIFS('CEO of the Qtr'!$H:$H,'Summary- FY 24-25'!$A$4,'CEO of the Qtr'!$I:$I,'Summary- FY 24-25'!G3) -> 12 | H4: =SUM(B4:F4) -> 39 | J4: Corporate | K4: =COUNTIFS('Job Well Done'!$F:$F,K3,'Job Well Done'!$J:$J,$J$4) -> 3 | L4: =COUNTIFS('Job Well Done'!$F:$F,L3,'Job Well Done'!$J:$J,$J$4) -> 14 | M4: =COUNTIFS('Job Well Done'!$F:$F,M3,'Job Well Done'!$J:$J,$J$4) -> 5 | N4: =COUNTIFS('Job Well Done'!$F:$F,N3,'Job Well Done'!$J:$J,$J$4) -> 7 | O4: =COUNTIFS('Job Well Done'!$F:$F,O3,'Job Well Done'!$J:$J,$J$4) -> 5 | P4: =COUNTIFS('Job Well Done'!$F:$F,P3,'Job Well Done'!$J:$J,$J$4) -> 10 | Q4: =SUM(K4:O4) -> 34
A5: West | B5: =COUNTIFS('CEO of the Qtr'!$H:$H,'Summary- FY 24-25'!$A$5,'CEO of the Qtr'!$I:$I,'Summary- FY 24-25'!B3) -> 5 | C5: =COUNTIFS('CEO of the Qtr'!$H:$H,'Summary- FY 24-25'!$A$5,'CEO of the Qtr'!$I:$I,'Summary- FY 24-25'!C3) -> 3 | D5: =COUNTIFS('CEO of the Qtr'!$H:$H,'Summary- FY 24-25'!$A$5,'CEO of the Qtr'!$I:$I,'Summary- FY 24-25'!D3) -> 10 | E5: =COUNTIFS('CEO of the Qtr'!$H:$H,'Summary- FY 24-25'!$A$5,'CEO of the Qtr'!$I:$I,'Summary- FY 24-25'!E3) -> 5 | F5: =COUNTIFS('CEO of the Qtr'!$H:$H,'Summary- FY 24-25'!$A$5,'CEO of the Qtr'!$I:$I,'Summary- FY 24-25'!F3) -> 2 | G5: =COUNTIFS('CEO of the Qtr'!$H:$H,'Summary- FY 24-25'!$A$5,'CEO of the Qtr'!$I:$I,'Summary- FY 24-25'!G3) -> 4 | H5: =SUM(B5:F5) -> 25 | J5: West | K5: =COUNTIFS('Job Well Done'!$F:$F,K3,'Job Well Done'!$J:$J,$J$5) -> 8 | L5: =COUNTIFS('Job Well Done'!$F:$F,L3,'Job Well Done'!$J:$J,$J$5) -> 0 | M5: =COUNTIFS('Job Well Done'!$F:$F,M3,'Job Well Done'!$J:$J,$J$5) -> 1 | N5: =COUNTIFS('Job Well Done'!$F:$F,N3,'Job Well Done'!$J:$J,$J$5) -> 2 | O5: =COUNTIFS('Job Well Done'!$F:$F,O3,'Job Well Done'!$J:$J,$J$5) -> 3 | P5: =COUNTIFS('Job Well Done'!$F:$F,P3,'Job Well Done'!$J:$J,$J$5) -> 0 | Q5: =SUM(K5:O5) -> 14
A6: East | B6: =COUNTIFS('CEO of the Qtr'!$H:$H,'Summary- FY 24-25'!$A$6,'CEO of the Qtr'!$I:$I,'Summary- FY 24-25'!B3) -> 0 | C6: =COUNTIFS('CEO of the Qtr'!$H:$H,'Summary- FY 24-25'!$A$6,'CEO of the Qtr'!$I:$I,'Summary- FY 24-25'!C3) -> 0 | D6: =COUNTIFS('CEO of the Qtr'!$H:$H,'Summary- FY 24-25'!$A$6,'CEO of the Qtr'!$I:$I,'Summary- FY 24-25'!D3) -> 0 | E6: =COUNTIFS('CEO of the Qtr'!$H:$H,'Summary- FY 24-25'!$A$6,'CEO of the Qtr'!$I:$I,'Summary- FY 24-25'!E3) -> 2 | F6: =COUNTIFS('CEO of the Qtr'!$H:$H,'Summary- FY 24-25'!$A$6,'CEO of the Qtr'!$I:$I,'Summary- FY 24-25'!F3) -> 2 | G6: =COUNTIFS('CEO of the Qtr'!$H:$H,'Summary- FY 24-25'!$A$6,'CEO of the Qtr'!$I:$I,'Summary- FY 24-25'!G3) -> 1 | H6: =SUM(B6:F6) -> 4 | J6: East | K6: =COUNTIFS('Job Well Done'!$F:$F,K3,'Job Well Done'!$J:$J,$J$6) -> 1 | L6: =COUNTIFS('Job Well Done'!$F:$F,L3,'Job Well Done'!$J:$J,$J$6) -> 0 | M6: =COUNTIFS('Job Well Done'!$F:$F,M3,'Job Well Done'!$J:$J,$J$6) -> 0 | N6: =COUNTIFS('Job Well Done'!$F:$F,N3,'Job Well Done'!$J:$J,$J$6) -> 0 | O6: =COUNTIFS('Job Well Done'!$F:$F,O3,'Job Well Done'!$J:$J,$J$6) -> 0 | P6: =COUNTIFS('Job Well Done'!$F:$F,P3,'Job Well Done'!$J:$J,$J$6) -> 0 | Q6: =SUM(K6:O6) -> 1
A7: North | B7: =COUNTIFS('CEO of the Qtr'!$H:$H,'Summary- FY 24-25'!$A$7,'CEO of the Qtr'!$I:$I,'Summary- FY 24-25'!B3) -> 12 | C7: =COUNTIFS('CEO of the Qtr'!$H:$H,'Summary- FY 24-25'!$A$7,'CEO of the Qtr'!$I:$I,'Summary- FY 24-25'!C3) -> 8 | D7: =COUNTIFS('CEO of the Qtr'!$H:$H,'Summary- FY 24-25'!$A$7,'CEO of the Qtr'!$I:$I,'Summary- FY 24-25'!D3) -> 4 | E7: =COUNTIFS('CEO of the Qtr'!$H:$H,'Summary- FY 24-25'!$A$7,'CEO of the Qtr'!$I:$I,'Summary- FY 24-25'!E3) -> 7 | F7: =COUNTIFS('CEO of the Qtr'!$H:$H,'Summary- FY 24-25'!$A$7,'CEO of the Qtr'!$I:$I,'Summary- FY 24-25'!F3) -> 5 | G7: =COUNTIFS('CEO of the Qtr'!$H:$H,'Summary- FY 24-25'!$A$7,'CEO of the Qtr'!$I:$I,'Summary- FY 24-25'!G3) -> 9 | H7: =SUM(B7:F7) -> 36 | J7: North | K7: =COUNTIFS('Job Well Done'!$F:$F,K3,'Job Well Done'!$J:$J,$J$7) -> 3 | L7: =COUNTIFS('Job Well Done'!$F:$F,L3,'Job Well Done'!$J:$J,$J$7) -> 2 | M7: =COUNTIFS('Job Well Done'!$F:$F,M3,'Job Well Done'!$J:$J,$J$7) -> 10 | N7: =COUNTIFS('Job Well Done'!$F:$F,N3,'Job Well Done'!$J:$J,$J$7) -> 12 | O7: =COUNTIFS('Job Well Done'!$F:$F,O3,'Job Well Done'!$J:$J,$J$7) -> 6 | P7: =COUNTIFS('Job Well Done'!$F:$F,P3,'Job Well Done'!$J:$J,$J$7) -> 6 | Q7: =SUM(K7:O7) -> 33
A8: South | B8: =COUNTIFS('CEO of the Qtr'!$H:$H,'Summary- FY 24-25'!$A$8,'CEO of the Qtr'!$I:$I,'Summary- FY 24-25'!B3) -> 5 | C8: =COUNTIFS('CEO of the Qtr'!$H:$H,'Summary- FY 24-25'!$A$8,'CEO of the Qtr'!$I:$I,'Summary- FY 24-25'!C3) -> 9 | D8: =COUNTIFS('CEO of the Qtr'!$H:$H,'Summary- FY 24-25'!$A$8,'CEO of the Qtr'!$I:$I,'Summary- FY 24-25'!D3) -> 13 | E8: =COUNTIFS('CEO of the Qtr'!$H:$H,'Summary- FY 24-25'!$A$8,'CEO of the Qtr'!$I:$I,'Summary- FY 24-25'!E3) -> 9 | F8: =COUNTIFS('CEO of the Qtr'!$H:$H,'Summary- FY 24-25'!$A$8,'CEO of the Qtr'!$I:$I,'Summary- FY 24-25'!F3) -> 12 | G8: =COUNTIFS('CEO of the Qtr'!$H:$H,'Summary- FY 24-25'!$A$8,'CEO of the Qtr'!$I:$I,'Summary- FY 24-25'!G3) -> 8 | H8: =SUM(B8:F8) -> 48 | J8: South | K8: =COUNTIFS('Job Well Done'!$F:$F,K3,'Job Well Done'!$J:$J,$J$8) -> 4 | L8: =COUNTIFS('Job Well Done'!$F:$F,L3,'Job Well Done'!$J:$J,$J$8) -> 9 | M8: =COUNTIFS('Job Well Done'!$F:$F,M3,'Job Well Done'!$J:$J,$J$8) -> 6 | N8: =COUNTIFS('Job Well Done'!$F:$F,N3,'Job Well Done'!$J:$J,$J$8) -> 3 | O8: =COUNTIFS('Job Well Done'!$F:$F,O3,'Job Well Done'!$J:$J,$J$8) -> 9 | P8: =COUNTIFS('Job Well Done'!$F:$F,P3,'Job Well Done'!$J:$J,$J$8) -> 7 | Q8: =SUM(K8:O8) -> 31
A9: Total | B9: =SUM(B4:B8) -> 30 | C9: =SUM(C4:C8) -> 28 | D9: =SUM(D4:D8) -> 34 | E9: =SUM(E4:E8) -> 32 | F9: =SUM(F4:F8) -> 28 | G9: =SUM(G4:G8) -> 34 | H9: =SUM(H4:H8) -> 152 | J9: Total | K9: =SUM(K4:K8) -> 19 | L9: =SUM(L4:L8) -> 25 | M9: =SUM(M4:M8) -> 22 | N9: =SUM(N4:N8) -> 24 | O9: =SUM(O4:O8) -> 23 | P9: =SUM(P4:P8) -> 23 | Q9: =SUM(Q4:Q8) -> 113
A11: SPOT and SPOT of the Month | J11: Intrafunctional
A13: Region / Quarters | B13: Spot | C13: Spot of the Month | D13: Total | J13: Q3 FY24 | K13: Q4 FY24 | L13: Q1-FY25 | M13: Q2-FY 25 | N13: Q3 FY25 | O13: Q4-FY 25 | P13: Total
A14: Corporate | B14: =COUNTIFS('Spot & Spot of the Month'!$I:$I,'Summary- FY 24-25'!A14,'Spot & Spot of the Month'!$F:$F,$B$13) -> 119 | C14: =COUNTIFS('Spot & Spot of the Month'!$I:$I,'Summary- FY 24-25'!A14,'Spot & Spot of the Month'!$F:$F,$C$13) -> 120 | D14: =SUM(B14:C14) -> 239 | J14: =COUNTIF(Sheet4!$B:$B,'Summary- FY 24-25'!J13) -> 1 | K14: =COUNTIF(Sheet4!$B:$B,'Summary- FY 24-25'!K13) -> 9 | L14: =COUNTIF(Sheet4!$B:$B,'Summary- FY 24-25'!L13) -> 5 | M14: =COUNTIF(Sheet4!$B:$B,'Summary- FY 24-25'!M13) -> 3 | N14: =COUNTIF(Sheet4!$B:$B,'Summary- FY 24-25'!N13) -> 5 | O14: 2 | P14: =SUM(J14:O14) -> 25
A15: West | B15: =COUNTIFS('Spot & Spot of the Month'!$I:$I,'Summary- FY 24-25'!A15,'Spot & Spot of the Month'!$F:$F,$B$13) -> 69 | C15: =COUNTIFS('Spot & Spot of the Month'!$I:$I,'Summary- FY 24-25'!A15,'Spot & Spot of the Month'!$F:$F,$C$13) -> 88 | D15: =SUM(B15:C15) -> 157
A16: East | B16: =COUNTIFS('Spot & Spot of the Month'!$I:$I,'Summary- FY 24-25'!A16,'Spot & Spot of the Month'!$F:$F,$B$13) -> 46 | C16: =COUNTIFS('Spot & Spot of the Month'!$I:$I,'Summary- FY 24-25'!A16,'Spot & Spot of the Month'!$F:$F,$C$13) -> 35 | D16: =SUM(B16:C16) -> 81
A17: North | B17: =COUNTIFS('Spot & Spot of the Month'!$I:$I,'Summary- FY 24-25'!A17,'Spot & Spot of the Month'!$F:$F,$B$13) -> 150 | C17: =COUNTIFS('Spot & Spot of the Month'!$I:$I,'Summary- FY 24-25'!A17,'Spot & Spot of the Month'!$F:$F,$C$13) -> 141 | D17: =SUM(B17:C17) -> 291
A18: South | B18: =COUNTIFS('Spot & Spot of the Month'!$I:$I,'Summary- FY 24-25'!A18,'Spot & Spot of the Month'!$F:$F,$B$13) -> 212 | C18: =COUNTIFS('Spot & Spot of the Month'!$I:$I,'Summary- FY 24-25'!A18,'Spot & Spot of the Month'!$F:$F,$C$13) -> 199 | D18: =SUM(B18:C18) -> 411
B19: =SUM(B14:B18) -> 596 | C19: =SUM(C14:C18) -> 583
A21: Debutant of the Quarter | J21: Cross Functional
A22: Region / Quarters | B22: Q3-FY24 | C22: Q4-FY24 | D22: Q1-FY25 | E22: Q2-FY25 | F22: Q3-FY25 | G22: Q4-FY 25 | H22: Total
A23: Corporate | B23: =COUNTIFS('Debutant of the Qtr'!$F:$F,B22,'Debutant of the Qtr'!$J:$J,'Summary- FY 24-25'!$A$23) -> 0 | C23: =COUNTIFS('Debutant of the Qtr'!$F:$F,C22,'Debutant of the Qtr'!$J:$J,'Summary- FY 24-25'!$A$23) -> 4 | D23: =COUNTIFS('Debutant of the Qtr'!$F:$F,D22,'Debutant of the Qtr'!$J:$J,'Summary- FY 24-25'!$A$23) -> 4 | E23: =COUNTIFS('Debutant of the Qtr'!$F:$F,E22,'Debutant of the Qtr'!$J:$J,'Summary- FY 24-25'!$A$23) -> 5 | F23: =COUNTIFS('Debutant of the Qtr'!$F:$F,F22,'Debutant of the Qtr'!$J:$J,'Summary- FY 24-25'!$A$23) -> 1 | G23: =COUNTIFS('Debutant of the Qtr'!$F:$F,G22,'Debutant of the Qtr'!$J:$J,'Summary- FY 24-25'!$A$23) -> 3 | H23: =SUM(B23:F23) -> 14 | J23: Q3 FY24 | K23: Q4-FY 24 | L23: Q1-FY 25 | M23: Q2-FY 25 | N23: Q3-FY 25 | O23: Q4-FY 25 | P23: Total
A24: West | B24: =COUNTIFS('Debutant of the Qtr'!$F:$F,B22,'Debutant of the Qtr'!$J:$J,'Summary- FY 24-25'!$A$24) -> 0 | C24: =COUNTIFS('Debutant of the Qtr'!$F:$F,C22,'Debutant of the Qtr'!$J:$J,'Summary- FY 24-25'!$A$24) -> 0 | D24: =COUNTIFS('Debutant of the Qtr'!$F:$F,D22,'Debutant of the Qtr'!$J:$J,'Summary- FY 24-25'!$A$24) -> 2 | E24: =COUNTIFS('Debutant of the Qtr'!$F:$F,E22,'Debutant of the Qtr'!$J:$J,'Summary- FY 24-25'!$A$24) -> 0 | F24: =COUNTIFS('Debutant of the Qtr'!$F:$F,F22,'Debutant of the Qtr'!$J:$J,'Summary- FY 24-25'!$A$24) -> 1 | G24: =COUNTIFS('Debutant of the Qtr'!$F:$F,G22,'Debutant of the Qtr'!$J:$J,'Summary- FY 24-25'!$A$24) -> 0 | H24: =SUM(B24:F24) -> 3 | J24: =COUNTIF(Sheet4!$G:$G,J23) -> 0 | K24: =COUNTIF(Sheet4!$G:$G,K23) -> 3 | L24: =COUNTIF(Sheet4!$G:$G,L23) -> 4 | M24: =COUNTIF(Sheet4!$G:$G,M23) -> 1 | N24: =COUNTIF(Sheet4!$G:$G,N23) -> 1 | O24: 5 | P24: =SUM(J24:O24) -> 14
A25: East | B25: =COUNTIFS('Debutant of the Qtr'!$F:$F,B22,'Debutant of the Qtr'!$J:$J,'Summary- FY 24-25'!$A$25) -> 0 | C25: =COUNTIFS('Debutant of the Qtr'!$F:$F,C22,'Debutant of the Qtr'!$J:$J,'Summary- FY 24-25'!$A$25) -> 0 | D25: =COUNTIFS('Debutant of the Qtr'!$F:$F,D22,'Debutant of the Qtr'!$J:$J,'Summary- FY 24-25'!$A$25) -> 0 | E25: =COUNTIFS('Debutant of the Qtr'!$F:$F,E22,'Debutant of the Qtr'!$J:$J,'Summary- FY 24-25'!$A$25) -> 0 | F25: =COUNTIFS('Debutant of the Qtr'!$F:$F,F22,'Debutant of the Qtr'!$J:$J,'Summary- FY 24-25'!$A$25) -> 0 | G25: =COUNTIFS('Debutant of the Qtr'!$F:$F,G22,'Debutant of the Qtr'!$J:$J,'Summary- FY 24-25'!$A$25) -> 0 | H25: =SUM(B25:F25) -> 0
A26: North | B26: =COUNTIFS('Debutant of the Qtr'!$F:$F,B22,'Debutant of the Qtr'!$J:$J,'Summary- FY 24-25'!$A$26) -> 0 | C26: =COUNTIFS('Debutant of the Qtr'!$F:$F,C22,'Debutant of the Qtr'!$J:$J,'Summary- FY 24-25'!$A$26) -> 0 | D26: =COUNTIFS('Debutant of the Qtr'!$F:$F,D22,'Debutant of the Qtr'!$J:$J,'Summary- FY 24-25'!$A$26) -> 2 | E26: =COUNTIFS('Debutant of the Qtr'!$F:$F,E22,'Debutant of the Qtr'!$J:$J,'Summary- FY 24-25'!$A$26) -> 1 | F26: =COUNTIFS('Debutant of the Qtr'!$F:$F,F22,'Debutant of the Qtr'!$J:$J,'Summary- FY 24-25'!$A$26) -> 2 | G26: =COUNTIFS('Debutant of the Qtr'!$F:$F,G22,'Debutant of the Qtr'!$J:$J,'Summary- FY 24-25'!$A$26) -> 1 | H26: =SUM(B26:F26) -> 5
A27: South | B27: =COUNTIFS('Debutant of the Qtr'!$F:$F,B22,'Debutant of the Qtr'!$J:$J,'Summary- FY 24-25'!$A$27) -> 0 | C27: =COUNTIFS('Debutant of the Qtr'!$F:$F,C22,'Debutant of the Qtr'!$J:$J,'Summary- FY 24-25'!$A$27) -> 0 | D27: =COUNTIFS('Debutant of the Qtr'!$F:$F,D22,'Debutant of the Qtr'!$J:$J,'Summary- FY 24-25'!$A$27) -> 1 | E27: =COUNTIFS('Debutant of the Qtr'!$F:$F,E22,'Debutant of the Qtr'!$J:$J,'Summary- FY 24-25'!$A$27) -> 0 | F27: =COUNTIFS('Debutant of the Qtr'!$F:$F,F22,'Debutant of the Qtr'!$J:$J,'Summary- FY 24-25'!$A$27) -> 0 | G27: =COUNTIFS('Debutant of the Qtr'!$F:$F,G22,'Debutant of the Qtr'!$J:$J,'Summary- FY 24-25'!$A$27) -> 1 | H27: =SUM(B27:F27) -> 1
B30: People Champion | J30: Thank You
A31: Region / Quarters | B31: Q3-FY25 | C31: Total | J31: Region / Quarters | K31: Total
A32: Corporate | B32: 4 | C32: =SUM(B32) -> 4 | J32: Corporate | K32: =COUNTIFS('Thank You'!$I:$I,'Summary- FY 24-25'!J32) -> 19
A33: South | B33: 1 | C33: =SUM(B33) -> 1 | J33: West | K33: =COUNTIFS('Thank You'!$I:$I,'Summary- FY 24-25'!J33) -> 9
J34: East | K34: =COUNTIFS('Thank You'!$I:$I,'Summary- FY 24-25'!J34) -> 9
J35: North | K35: =COUNTIFS('Thank You'!$I:$I,'Summary- FY 24-25'!J35) -> 22
J36: South | K36: =COUNTIFS('Thank You'!$I:$I,'Summary- FY 24-25'!J36) -> 47

Sheet Process Document
A1: Ongoing
A2: Award | B2: Purpose | C2: Nominator ELigibility | D2: Eligibility | E2: Approval | F2: Vantage circle points
A3: Thank You | B3: Thank You badge is to express gratitude to colleagues who went beyond their call of duty to help their colleagues | C3: All | D3: All | E3: - | F3: -
A4: SPOT | B4: Employees can appreciate their colleagues for the demonstration of CEOs behaviours of Collaboration, Experimentation, Ownership and Speed and recognize them for their contribution, achievement and impact. | C4: All | D4: All | E4: - | F4: Eligibility for Spot of the Month
A5: Be Your Own CEOs
A6: Award | B6: Purpose | C6: Nominator ELigibility | D6: Eligibility | E6: Approval | F6: Vantage circle points
A7: Spot of the Month | B7: A monthly award for employees who have demonstrated CEOs behaviours and have had significant impact through achievement beyond day to day work. | C7: Via Spot | D7: 1. Via Spot | E7: M2 | F7: 500
C8: People Manager | D8: 2. Direct -> M3 to M5 employees
A9: CEOs of the Quarter | B9: A quarterly award to recognise employees who have demonstrated CEOs behaviours of Collaboration, Experimentation, Ownership and Speed and made an exemplary contribution through a pathbreaking idea or solution, to the function/organization, going beyond the call of duty. | C9: From the approved "SPOT of the month" of the past 3 months | D9: Spot of the Month | E9: M2 Jury | F9: Invitation to CEOs Forum
A10: Quarterly awards
A11: Award | B11: Purpose | C11: Nominator ELigibility | D11: Eligibility | E11: Approval | F11: Vantage circle points
A12: Job Well Done | B12: To recognise employees who have demonstrated Tata Play Anchor competencies in their work | C12: People Manager (within the same department) | D12: M3 to M5 employees | E12: M2 -> M1 | F12: 5000
A13: Debutant of the Quarter | B13: To recognise new joiners who blend with their peers and contribute through innovative thoughts and ideas | C13: People Manager (within the same department) | D13: M3 to M5 employees who have joined in a previous quarter | E13: M2 -> M1 | F13: -
A14: Intra Functional Team Awards | B14: To recognise intra functional teams who have displayed exceptional Anchor behaviours, collaborated on specific projects, and delivered positive results | C14: People Manager (within the same department) | D14: M3 to M5 employees who are part of same function | E14: M1 | F14: 10,000 divided equally to team members
A15: Cross Functional Team Awards | B15: To recognise cross functional teams who have displayed exceptional Anchor behaviours, collaborated on specific projects, and delivered positive results | C15: People Manager (across departments) | D15: M3 to M5 employees who are part of different functions | E15: M1 Jury | F15: 10,000 divided equally to team members
A16: Half-Yearly awards
A17: Award | B17: Purpose | C17: Nominator ELigibility | D17: Eligibility | E17: Approval | F17: Vantage circle points
A18: People Champion | B18: To recognise people managers for their efforts in creating a strong workplace which facilitates the employee to grow, engage and contribute to the fullest. | C18: People Manager (within the same department) | D18: People Manager | E18: M1 | F18: -
A19: Other awards
A20: Pathfinder Award
A21: Fundamental Award | B21: Basis activities conducted for respective regions

Sheet Sheet3
A2: CE
A3: Count of Sl No. | B3: Column Labels
A4: Row Labels | B4: Q1-FY25 | C4: Q2-FY 25 | D4: Q3-FY24 | E4: Q3-FY25 | F4: Q4-FY24 | G4: Grand Total
A5: Corporate | B5: 7 | C5: 9 | D5: 8 | E5: 7 | F5: 8 | G5: 39
A6: East | C6: 2 | E6: 2 | G6: 4
A7: North | B7: 4 | C7: 7 | D7: 12 | E7: 5 | F7: 8 | G7: 36
A8: South | B8: 13 | C8: 9 | D8: 5 | E8: 12 | F8: 9 | G8: 48
A9: West | B9: 10 | C9: 5 | D9: 5 | E9: 2 | F9: 3 | G9: 25
A10: Grand Total | B10: 34 | C10: 32 | D10: 30 | E10: 28 | F10: 28 | G10: 152

Sheet Sheet4
A1: Citation | B1: Quarter | F1: Citation | G1: Quarter
A2: Sony RIO was a very complex and a unique project which involved various teams within commercial function. The project helped rationalise subscribers content and also impact monthly charges. It was a complex project which involved making changes packaging and meeting regulatory compliances within timelines. Post execution the task was to roll it back as well with speed and efficiency as business objectives were achieved. This team worked very closely and their collective efforts demonstrated successful collaboration, ownership, speed and innovation with a focus on not just business KPIs but also on customer experience | B2: Q2-FY 25 | F2: Launch of Tata Play Superhit Serials At all levels, this was a project launched well and doing well despite very many challenges. It has been, at idea level, well thought out and well researched product after much debate between extension of classic TV vs standalone product. Example of good partner negotiation wherein for the first time, star agreed to create launch promos and create conceptual promos every month. Star also created special 1 hours edits of all shows despite the large cost. Overall, product idea, partner negotiations, new experiments in GTM, new formats of slate promos, appreciation by subscribers for bringing this product and great numbers makes this a superhit product of the year. All teams involved has put in wholehearted efforts to make this happen. | G2: Q2-FY 25
A3: Sunil is number one in overall Ranking in first six Month . Bhaskar is number 1 in Building Infra in his respective area across Circle | B3: Q2-FY 25 | F3: The project involved changing the existing Prime Video journey and implementing a new activation journey for Prime Video with all eligible Binge packs. This required altering all backend and Frontend statuses and stages for Amazon Prime Video.\n- end-to-end testing in UAT and Production environments.\n- 185 test cases prepared and executed in a single day in coordination with teams, identifying over 50+ issues.\n- Multiple teams coordinated on daily basis to resolve open issues, ensuring successful closing.\n- Prime Video rigorous testing with all eligible Binge packs as per business requirement and brought the integration successfully in live production.\n- Simultaneously performed regression testing for the Binge TV app and ad-hoc testing as well. | G3: Q1-FY 25
A4: TATA Play was migrating to a new SIEM tool, however, due to the TBXG Cyber Assessment, the DTH team started a little late. With just ~10 days remaining before the existing SOC contract expired, Ritesh and Swamy took charge of the situation and successfully onboarded all major log sources within the tight timelines by collaborating with multiple teams and putting in long hours to ensure a smooth transition. | B4: Q2-FY 25 | F4: In the month of May\u201924, we embarked on an ambitious initiative aimed at re-activating and ringfencing customers from the deep deactive bucket during the high opportunity T20 world cup season. We targeted 5 million subscribers from the D30 to D365 bucket with active days less than 240 in the past 12 months. By leveraging a multi-channel approach\u2014 which includes Outbound, Inbound, SMS, WhatsApp, OBD. \u2014we will have successfully retained and Winback more than 110K subs subscribers by the end of this activity. Cross functional teams were involved in planning, developing infrastructure, hiring and training of close to over 3000 resources, with a effective outcome of more than 110,000 conversions coming back with long term commitment (6month/12 month). The success of our Mega Winback Initiative underscores the importance of a multi-faceted approach, Speed and effective cross-functional collaboration. Push through Outbound, Inbound, WhatsApp, SMS, OBD led to a healthy conversion and returns. | G4: Q1-FY 25
A5: We launched a first of a kind partnership with Amazon Prime Video for Binge customers, offering Prime Lite as part of a 199(INR) best of 6 bundle. This strategic move aimed to launch a powerful & unique proposition for consumers to choose their favourite OTTs on a very aggressive price point. This ensured that we have a strong market pull for driving acquisition & thus aspire for 1 Mn Sub-base. It involved collaboration across teams to implement the proposition across multiple touchpoints, including both front-end and back-end product development creating customer experience & pack journeys. A robust marketing campaigns was launched with an ad-film along with tentpole Content (Mirzapur & Panchayat) across Digital & Ch 100. This created a high impact launch, achieving ~200K gross additions within the first couple of months which is the highest for Binge. | B5: Q1-FY25 | F5: Synamedia CY23 Bundle testing & download completion\nConsisting\u00A0of 9 different feature enhancements like 3 additional language in EPG, 1500 service capability in STB, subscriber channel indication and other marketing CRs for 18 field STB models. This required\u00A0arranging software deliveries, rigorous testing of multiple software releases in coordination with relevant configurations setup from the Headend team, getting issues fixed , conducting trial & target zip code based download for every STB model each day.\nResult achieved : successful software upgrade completion without major escalations from field.\n\u00A0 | G5: Q1-FY 25
A6: Team AI Evangelists:\nProject AI Literacy (PAL) has been taken up by a team, AI Evangelists comprising of Ishant, Dimple, Varun, Prabhat & Anantha. The project aims to ensure that by the end of 52-week period each of the Finance team member is familiar with the new age Tech tools and their impact on them both professionally & personally. \nAs part of this project already 10 modules have been published. Also the team has carried out multiple interactive sessions that have been well received. There is an overwhelming response and a change has set in. \nThe team sourced the course and extent of this project by referring to CBSE X syllabus of AI subject. They have referred to various materials across the internet sources, using GenAI tools to create the modules that are easy to read with pop culture references incl. Bollywood.\u00A0 | B6: Q1-FY25 | F6: Launch of targeted ads on Star channels Team collaborated to Launch an industry-first paid ad innovation Q1\u2013 Targeted ads on Star GEC and Sports contributing to the gross revenue of Rs. 1.6 Cr (Gross) activating brands like Apple, River soft, Amazon prime, Amazon Fresh, Gemini Edible oils, Rupay & Torrent pharmaceutical | G6: Q1-FY 25
A7: Recognizing the team with Intra Function Award for the below contributions towards 5Million Mega Winback Campaign.\n1. From day one, 5mn reports were expected by 9am and hence team had to login early shifts for churning the data and sharing the same on time.\n2. Few new campaigns under the same Mega WBK (Follow-up Phase 1, OB&WA Follow-up, Act/Deact Follow-up Phase 2 were introduced at regular intervals which increased the query run time & team worked together in optimizing the same using online techniques \n3. A new dashboard was introduced which is being sent to CEO on a daily basis by 9am, timeline was never missed & teams across functions worked on the same for seamless delivery. (Lenin to update dials & Conversions, Sujith to share FTE count, Srinidhi to share cost on a daily basis, Pavan Jagan's contribution towards CR's & Billing Closure), this report is sent on all days including Weekends and Holidays. \n4.Error free & timely delivery of reports helped in campaign success. | B7: Q1-FY25 | F7: The Delinking of Binge from DTH on the Binge+ STB was a complex project that brought together business, product and execution teams across platforms, to collaborate on a common goal and delivering under strict timelines. The objective was to empower customers with the flexibility to pay for Linear TV or OTT or both using Tata Play wallet. From a business perspective, this was an opportunity to bring back many of our lost customers who wanted to consume only Binge on their Binge+ box. A solution was needed to achieve these rules without impacting other adjacent DTH workflows, UX definition across the different customer touchpoints on different platforms like the Binge+ box and TPMA & finally in the testing & sign off of one of the most detailed set of use cases.The impact of this project post go-live has been a healthy \u2013 with 10% adoption of this feature by customers, with minimal revenue impact on DTH side, reflecting the customer value in these changing times.\u00A0 | G7: Q4-FY 24
A8: I would like to nominate Anand, Shoaib, and Vinod for the Intra-Functional Team Award for their exceptional performance in Q1. Their collaboration and dedication have led to outstanding results, significantly contributing to our overall success. Key Achievements: *Exceeded CESIP Target: The team achieved more than 125% of the CESIP appointment target, showcasing their dedication and strategic execution. *Strategic Partner Appointments: Their successful appointment of CESIP partners is crucial for our business, as TV installers play a vital role in convincing customers to choose Tata Play. *APD Business Growth: With the new CESIP partners onboard, they are now poised to initiate and ensure growth in the APD business. Their teamwork, strategic thinking, and commitment have been exemplary. I strongly recommend this team for the Intra-Functional Team Award to recognize their significant contributions and encourage their continued success. Congratulations to all. | B8: Q1-FY25 | F8: In Orissa Sales & team service team jointly executed big & complex projects(IFFCO) where more than 1200 connections being given with in time line with out any escalations.The smooth execution of big projects enable team motivations and given boost to market which fetches more similar project like this..This is showing a great example of collaborative approach team working with one single objectives of best of customer satisfaction and win over competition. | G8: Q4-FY 24
A9: First time since the time of inception of Tata Play, Customs Audit covering all the import and export transactions for the last 5 years i.e. from 2018 to 2023 happened this year. This was a premise-based audit which continued for the 2 months period through multiple meetings and engagements with Auditors, submission of series of relevant documents asked by auditors and ended with 2 full days visit by 3 authorities from customs audit department in our corporate office. Bhupendra Kumar and Harish Jathan have handled end to end documentation, liaising with cross functional stakeholders, solving of all the queries raised by auditors and finished the audit with clean report without any major observations. Being the audit happening for the first time, it was a difficult task to handle complicated queries and situations raised by Auditors. But Bhupendra and Harish have made best use of their knowledge and experience to handle these situations effectively and resolved all open queries timely. | B9: Q1-FY25 | F9: This recognition for the team that has worked together on putting up signages for Project Ravi and Versova across locations with agility. The cross functional team between Comms, Procurement and Trade Marketing worked as team to ensure newly opened outlets are given visibility support in quick time. The team set up a network of agencies and vendors with a monitoring system to ensure deliverables moved on time and were tracked. | G9: Q4-FY 24
A10: With a new satellite being commissioned the team was tasked to create impact and deliver ROI on the satellite cost. In the last 3 months of the fiscal, the team was persistent and demonstrated rigour in securing partnerships thus delivering the highest carriage collections seen across the last 5 years amounting to 60 Crs in revenue in 3 months. This contributed significantly to overall revenue for Tata Play. | B10: Q4 FY24 | F10: Launch of Tata Play Deiveegam<br/> The launch of Tata Play Deiveegam marked a significant milestone as our first regional devotional service after Aradhana. Recognizing the importance of the South Indian market, we chose Tamil for its enthusiasm and receptiveness to a premium offering, setting the price at ₹60 per month—a first for any Tata Play regional service.<br/>Meticulous research, extensive planning and seamless collaboration across teams to sell the service to the right target group. The results were immediate, with Tata Play Deiveegam setting a new benchmark in the regional devotional space in its launch week. <br/>Key milestones:<br/>Deiveegam was launched at 33% higher price still achieved similar gross adds (14-15k) as Tamil classics and Telugu classics in the first 7 days.<br/>Revenue generated by Deiveegam was significantly higher than other regional services by 16-20%<br/>This launch has set a best practice to be replicated for pricing interventions in other regional services and drive revenue | G10: Q3-FY 25
A11: The team streamlined the planning & execution for implementing SEO on Binge, it was the first of its kind project with no in house expertise and required every team member to go above and beyond to get it LIVE . Right from identifying keywords to website design ,technical and programming aspects of the website, the team ensured that the Binge website was made SEO friendly for organic ranking on Google search and will give long term benefits of organic marketing. | B11: Q4 FY24
A12: Inbound team had taken an arduous task of achieving NPS of 70 this year compared to 57 last year. This required a lot of brainstorming, project mapping, cross functional stake holder management, process changes, introducing new monitoring mechanism etc. Every individual had taken a specific region and PI\u2019s to improve upon from April to December. The overall project was divided into Six Sigma and 360-degree feedback learning to be incorporated into practice. NPS has moved from 57 last to 71 in December with YTD NPS being at 70 which is best ever for us and across industries. The entire team and every individual have demonstrated a rare passion to achieve the goals with excellent call to action. Not only the scores were improved drastically but also NPS is almost insular now to process changes and exhibiting a process level stability. A great foot to achieve with astounding teamwork. Keep it up team!\u00A0 | B12: Q4 FY24
A13: This Award Goes to each ASM of Team Marathwada for all their hard work in Delivering Result in Q4 & Hitting Hat Trick of West Region Award too with Highest TSK Active Dealer Achievement in the month of March 2024. Congratulations Team & Keep it up! | B13: Q4 FY24
A14: Good Job Done Team! you guys have adopted the change and action on task and delivered 100% result within timeline.Task was TSK active Target 2150 by Dec 2023. & Achievement was 2154 & given Growth over July is 65%. which the highest in Pune district.your contribution is more than 100% ASM Name\u00A0 Q3 Tgt Q3 Ach\u00A0 Ach%\u00A0 Sachin Gaikwad 1237 1477 119% Vikas Desai 1168 1286 110% Mohsin Tamboli 1244 1536 123% | B14: Q4 FY24
A15: Monish and Sahil have contributed very well in success of Sales and Revenue Performance for CO OB function. with 9% reduction in cost, we have 10% growth in Conversions and Gross Revenue. We will be doing 5X ROI with 180 CR revenue from OB CO Team. Their contribution is highly commendable with keeping Compliance intact. Commercial team has shared accolades for their contribution. Congratulations to both of them for their good work for FY 23-24. | B15: Q4 FY24
A16: Excellent job for achieving more than 80% ISP Installer contribution for BMP contribution with in 21 days of the month. Across ASMs has contributed and strong activity to the field level & sense of urgency has been showing.The similar trend showing in Recharge as well , every ASM now contributing to over all circle numbers and as a Circle we are now contributing highest numbers for both BMP and Recharges on many days to region..This is the step stone for big success for coming days, with this engagement level we as a team can achieve more such success.. | B16: Q4 FY24
A17: As A Team All managed MDU migration load efficiently within timelines. They prepared well in advance manpower and started following up daily plan vs Achievement. They coordinated well with ODU teams in handling all institutional subscribers along with VIP subscriber with least escalation and minimum break down time with MDU migration hand in hand West having Highest MDU base of 23803 buildings, still we able to Migrate all subs as per given timelines. | B17: Q4 FY24
A18: We took a bold target of doing 100,000 Gross adds of Tata Play Services through TPMA at the start of the year. The number then was 30K. The team took this as a challenge. Collaboratively, they devised strategies on how to achieve it and achieved the targets in March. A true example of collaboration, strategic thinking and execution excellence. | B18: Q4 FY24
A19: The BE Team worked very hard for CD 6.0 of Binge. The exercise was first project and was highly appreciated by Samba Sir and Harit Sir too. Based on the same actions are being taken. What is important to note that the Final presentation that had to be done ib December 2023 was preponed to 22nd November 2023 based on a decision in Factbook which was held around 17th Nov 2023. The BE Team gathered together and turned it around to deliver the Final presentation on 22nd November 2023 which was on the basis of 500 Calls of Customers analysed for the outcome of Pain Points to be addressed. Samba Sir also send an email to the Finance Team appreciating this effort and also stating that such process of fast Turn around should be noted and imbibed by each individual. | B19: Q3 FY24
A20: Almost all content viewing apps have hero banners as a norm. The radical thought of not having a hero banner for TPMA warranted a A/B testing. As it could potentially have impact on business KPI and customer experience. A/B testing as a solution was not available and hence had to get developed. For doing the test it was also critical that we had the baseline of KPI’s available across content viewing and upselling and their CTR’s. The launch of AB testing required it to be prioritized in the road map along with business rules being put in place. It also required a new UI to be created along with localization. The period for this testing was also critical as we wanted to test this with and without a sporting event. Last but not the least it required a mindshift change to go against the norm. A/B testing was launched in November and we monitored the performance over 14 days. The results were interesting. It showed that not having a hero banner did not have any adverse impact on business. | B20: Q3 FY25
A21: With over 20 new releases on Tata Play Binge every week, across partner apps, there was an opportunity to ride on the popularity and buzz of the titles and leverage that to drive higher subscriptions and engagement for Binge. The team identified the high-decibel content releases to create a seamless end-to-end strategy: procuring trailers and promos, crafting compelling assets, and deploying them across multiple touchpoints including Ch 100, set-top boxes, Binge App, TPMA, emailers, notifications, digital platforms, social and field communication. What sets this initiative apart is the agility - despite tight timelines with partners delivering assets just days or even hours before launch, the team has executed flawless go-to-market plans, ensuring maximum impact. | B21: Q3 FY25
A22: Would like to extend appreciation to the team for their dedication and collaboration for the successful launch of the Quality Framework- 'NEF' for SR desk.<br/>Team created comprehensive Quality framework, stringent guidelines, ensured training sessions, calibrations, simplifying the guidelines, system enhancements for higher efficiencies and collaborated with partners to ensure seamless integration and adoption of the new framework. The new framework has resulted in higher accuracies and quicker resolution <br/> | B22: Q3 FY25
... A24: RO Antennas old Feed system replacement with Krato’s feed got Carried out by In-house team members: Required to replace old Feed system of RO-Antennas and need to install new feed along with New LNB changeover system with Acrylic Protection Assembly for entire feed system, Tech Services team members taken ownership for this critical installations and completed the same on required Antennas.<br/><br/>Installation and Replacement Rack power MDU’s EATON STS-16 units with EATON-ATS-16, To prevent equipment power failures in Compression system AVP racks old EATON STS-16 units which are having switching issues required to be replaced with New EATON ATS units, Tech Services team taken ownership and worked responsibly during Scheduled Activity timings and completed the critical MDU units replacement activity successfully. | B24: Q3 FY25

Sheet CEO of the Qtr
A1: Sl No. | B1: Emp ID | C1: Name | D1: Citation | E1: Grade | F1: Designation | G1: Department | H1: Region | I1: Quarter | J1: Award Name | K1: Award Name Quarter
A2: 1 | B2: 7347 | C2: Anilkumar N | D2: Amitabh Das - I really appreciate the effort put in by you in configuring the UNICA campaign for Binge Mobile Flexi 99 OB campaign Launch. You took end to end responsibility from raising the CR, to coordinating closely with IT and UAT teams to ensure the solution is created, tested, and deployed seamlessly within a very stiff timeline. A big thanks for your support and ownership. | E2: M5 | F2: Assistant Manager - Systems Solutions & Design - COSSG | G2: Customer Operations | H2: South | I2: Q4-FY24 | J2: CEO of the Quarter | K2: =_xlfn.CONCAT(J2," ",I2) -> CEO of the Quarter Q4-FY24
A3: 2 | B3: 4149 | C3: Joby George | D3: Lolakshi Ashok Moolya - The Department of Telecommunications (DOT) issued an Office Order on October 1, 2022, eliminating NOCC charges for using the Space segment. TATA Play had already made advance payments to DOT for the entire year. Upon the order taking effect, efforts were made, particularly by Joby, who played a crucial role in meeting with officials to initiate the refund process. This involved extensive sharing of reconciliation and data to demonstrate timely payment of old dues. Finally, in September 2023, the refund was successfully received. Additionally, following the activation of GSAT 24, Joby diligently pursued the refund of WPC License fees paid in advance. After persistent follow-ups, a senior official agreed to offset these fees against the next year's Spectrum fees. The commendable efforts of Joby in navigating the complexities of government authorities to secure these refunds are truly appreciated. | E3: M3 | F3: Assistant General Manager - Regulatory Affairs | G3: Legal | H3: North | I3: Q4-FY24 | J3: CEO of the Quarter | K3: =_xlfn.CONCAT(J3," ",I3) -> CEO of the Quarter Q4-FY24
A4: 3 | B4: 6805 | C4: Kumar Shubham | D4: Shubham has played a pivotal role in assisting in setting up processes and spearheading the signage project Ravi and Versova. He brings to the table the ability to understand trade, the potential challenges on a project and managing key stakeholders through his relationships. Shubham has been relentless and reliable team member to ensure that the signage project keeps rolling on-time and in-full. He has also contributed to ensuring timely deliveries and execution of the long- term visibility elements including innovative elements such as sturdy standees in 2023 that has benefited the trade/business to a large extent. | E4: M4 | F4: Senior Manager - Brand Marketing | G4: Communications | H4: Corporate | I4: Q4-FY24 | J4: CEO of the Quarter | K4: =_xlfn.CONCAT(J4," ",I4) -> CEO of the Quarter Q4-FY24
A5: 4 | B5: 6375 | C5: P Yogapriya . | D5: Ritesh Jain ( Commercial )-Yoga has extremely well managed 'Next Best Action' project. Right from creating Business Requirement Document to coordinating with various teams (Analytics, IT, Customer Operations..) and making sure that project is on track, Yoga has been instrumental in making this project successful. Intelligent product rules have been designed which made sure that subscribers are recommended right product there by maximizing the revenue opportunity. She made sure that at every step all the teams are aligned on the objective of the project leading to timely closure of the project. Post go live reporting has been also taken care of, daily reporting is helping teams to drive business better. Overall, an excellent work done on NBA. Keep up the good work Yoga. | E5: M4 | F5: Senior Manager - Subscriber Marketing | G5: Commercial | H5: Corporate | I5: Q4-FY24 | J5: CEO of the Quarter | K5: =_xlfn.CONCAT(J5," ",I5) -> CEO of the Quarter Q4-FY24
A6: 5 | B6: 7644 | C6: Sachin Ravasab Janaj | D6: Anitha Joy ( Commercial )-Sachin has helped the content ops team in automating the daily schedule process for Tata Play Fun Learn , being new in the organisation, Sachin has been able to quickly understand content teams schedule requirement and has developed a tool to generated the various output schedules like Playout, EPG , AMS , Application schedule etc . Team used to take good amount of time to generate these schedules manually are now able to generate them with ease and manual errors are minimized through system generated schedules. Thank you Sachin. | E6: M5 | F6: Executive - New Product Development | G6: Commercial | H6: South | I6: Q4-FY24 | J6: CEO of the Quarter | K6: =_xlfn.CONCAT(J6," ",I6) -> CEO of the Quarter Q4-FY24
A7: 6 | B7: 6356 | C7: Sushant Awasthi | D7: Naveen Rawal ( Technology )-For a potential customer on white label product, the requirement was to provide them with detailed performance review of their existing STB and accessory items and hence offer our expertise. Sushant took ownership and successfully completed the hardware reliability testing activity on the received sample units within short span of time with critical improvement findings in the product. Sushant's contribution and commitment in completing this activity is valued and appreciated. Keep it up. | E7: M5 | F7: Assistant Manager - Consumer Technology | G7: Technology | H7: North | I7: Q4-FY24 | J7: CEO of the Quarter | K7: =_xlfn.CONCAT(J7," ",I7) -> CEO of the Quarter Q4-FY24
A8: 7 | B8: 7658 | C8: Kaushal Kumar Jha | D8: Meghana Nagaraj - Kaushal, I would like to express my appreciation for your outstanding contribution to taking Notifications live on Binge+. You took ownership of the project end to end and collaborated with Business & Technology teams, playing a crucial role in prioritization, negotiating timelines, technical discussions & managing stakeholder expectations to ensure the feature was taken live with a significant impact on the engagement KPIs. Your dedication is truly commendable and deeply appreciated! Your enthusiasm and determination always reflect in your outputs. Keep up the good work! | E8: M4 | F8: Senior Manager - New Product Development | G8: Commercial | H8: South | I8: Q4-FY24 | J8: CEO of the Quarter | K8: =_xlfn.CONCAT(J8," ",I8) -> CEO of the Quarter Q4-FY24
A9: 8 | B9: 7640 | C9: Cheril Mehta | D9: Cheril, the effort that you have put into making Notifications on Binge+ live is remarkable. All the CLM and promotional campaigns planned and executed by you to every last detail to win back Binge customers on Binge+ & to improve engagement of existing customers have been having a significant impact on the KPIs & this will only improve further. Your collaborative spirit and willingness to support others have helped in making this possible. Not to mention, your attention to detail that makes you more unique. Your dedication is truly commendable and deeply appreciated! Keep up the good work! | E9: M4 | F9: Manager - Subscriber Marketing | G9: Commercial | H9: Corporate | I9: Q4-FY24 | J9: CEO of the Quarter | K9: =_xlfn.CONCAT(J9," ",I9) -> CEO of the Quarter Q4-FY24
A10: 9 | B10: 6745 | C10: Shriram Mahajan | D10: Shriram Congratulations on your ever Highest Achievement of TSK Active for the month of March 2024 ! Keep it up | E10: M4 | F10: Manager - Trade Sales | G10: Sales | H10: West | I10: Q4-FY24 | J10: CEO of the Quarter | K10: =_xlfn.CONCAT(J10," ",I10) -> CEO of the Quarter Q4-FY24
A11: 10 | B11: 5129 | C11: Aditya Sharma | D11: Sandeep Mann ( Technology )-Aditya has been crucial in helping us getting the RECD work completed for DG Sets which was supposed to be completed by 31st Dec 23, he helped us to get the PO released for this work at a very brisk rate coordinating with all the stake holders, we deeply appreciate his dedication and competence which demonstrated Collaboration, ownership, speed for the closure of subjected issue which helped us to comply with the govt guidelines well before the deadlines. | E11: M3 | F11: General Manager - Supply Chain Services | G11: Finance | H11: North | I11: Q4-FY24 | J11: CEO of the Quarter | K11: =_xlfn.CONCAT(J11," ",I11) -> CEO of the Quarter Q4-FY24
A12: 11 | B12: 7667 | C12: Janarthanan Thangavelu | D12: Truly appreciate Jana for optimizing BI operations stream. Since 3 last months there are no issues in month end processing, everything went smooth. Thanks for building BI Operation Dashboard which is extremely helpful to business owners to track their RR status directly from MS teams channel seamlessly.Superb work demonstrated. Keep it up. | E12: M4 | F12: Senior Manager - IT Delivery | G12: IT | H12: South | I12: Q4-FY24 | J12: CEO of the Quarter | K12: =_xlfn.CONCAT(J12," ",I12) -> CEO of the Quarter Q4-FY24
A13: 12 | B13: 7157 | C13: Suraj Pandey | D13: Prasanna Kumar Singh ( Sales )-I appreciate your effectiveness and precision in managing MDU installation in and around Lucknow. We are acquiring hotels and other commercial establishments on a good speed and your support in installing MDU set up at these places is recognised. You not only help us in giving installations with a good speed and deliver always on time, but also you own your commitment. Keep up this good work. | E13: M5 | F13: Assistant Manager - Field Service Delivery | G13: Field Service Delivery | H13: North | I13: Q4-FY24 | J13: CEO of the Quarter | K13: =_xlfn.CONCAT(J13," ",I13) -> CEO of the Quarter Q4-FY24
... A105: 104 | B105: 7250 | C105: Prachodaya Das | D105: Anitha Joy (Commercial) -Need to appreciate Prachodaya for quick collaboration and speed to go live of ten floaters along with the 1 alias services, in terms of required information like EPG No., genre and the schedules for the same with which has helped revenue teams to monetize the additional bandwidth of GSAT-24. Thank you. | E105: M4 | F105: Manager - Subscriber Marketing | G105: Commercial | H105: Corporate | I105: Q3-FY24 | J105: CEO of the Quarter | K105: =_xlfn.CONCAT(J105," ",I105) -> CEO of the Quarter Q3-FY24
A106: 105 | B106: 7237 | C106: Lakshya Lohumi | D106: YashasviGupta (Commercial) -Lakshya has been driving daily content led campaigns for Binge mobile app on Clevertap with rigour and ownership. This entails sending notifications basis content go-live and even on weekends. She has played pivotal role in go-live of new payment gateway (PayU) for Binge mobile and has good grip and understanding of transaction journeys and dashboards which has been of great help in improving transaction success rates for the new PG. Kudos to the efforts and wishing her good luck to keep up the good work. | E106: #N/A | F106: Manager - Subscriber Marketing | G106: Commercial | H106: Corporate | I106: Q3-FY24 | J106: CEO of the Quarter | K106: =_xlfn.CONCAT(J106," ",I106) -> CEO of the Quarter Q3-FY24
A107: 106 | B107: 7123 | C107: Kumar Gaurav | D107: Vijay Chandel (Technology) -Gaurav took Ownership and modified Service Count report during Satellite Migration activity carried on GSAT24 and GSAT 1O services including addition of 15 Transponders. Which help us to keep track of services within Tata Play Platform. | E107: M5 | F107: Assistant Manager - Broadcast operations | G107: Technology | H107: North | I107: Q3-FY24 | J107: CEO of the Quarter | K107: =_xlfn.CONCAT(J107," ",I107) -> CEO of the Quarter Q3-FY24
